[root][2020-06-16 16:25:01][2020-06-16 16:25:01][    111347]:  FATAL:  database "yjy015_1" does not exist

[root][2020-06-16 16:25:01][2020-06-16 16:25:01][    111347]:  Traceback (most recent call last):
  File "/home/YJY015/code/download.py", line 163, in <module>
    searchinfos=pga.search_db_table(db_name,table_name,cdt_element)
  File "/home/YJY015/code/db/postgres_archive.py", line 143, in search_db_table
    conn = psycopg2.connect(database=database_name, host=self.host, user=self.user, password=self.password, port=self.port)
  File "/root/anaconda3/lib/python3.7/site-packages/psycopg2/__init__.py", line 126, in connect
    conn = _connect(dsn, connection_factory=connection_factory, **kwasync)
psycopg2.OperationalError: FATAL:  database "yjy015_1" does not exist


[root][2020-06-16 16:45:06][2020-06-16 16:45:17][    129495]:  Traceback (most recent call last):
  File "/home/YJY015/code/file_info/wget_download.py", line 734, in download_wget
    self.record_datas()
  File "/home/YJY015/code/file_info/wget_download.py", line 667, in record_datas
    self.record_data(self.localfilename)
  File "/home/YJY015/code/file_info/wget_download.py", line 459, in record_data
    self.db_file_size=os.path.getsize(self.downloadfullpathname)
  File "/root/anaconda3/lib/python3.7/genericpath.py", line 50, in getsize
    return os.stat(filename).st_size
FileNotFoundError: [Errno 2] No such file or directory: '/home/YJY015///data//hybrid/SWPC/json/goes_int_proton/202006/20200616/differential-protons-1-day_20200616_084500.json'

During handling of the above exception, another exception occurred:

Traceback (most recent call last):
  File "/home/YJY015/code/file_info/wget_download.py", line 873, in start
    self.download_wget(starttime, endtime)
  File "/home/YJY015/code/file_info/wget_download.py", line 741, in download_wget
    raise Exception(traceback.format_exc())
Exception: Traceback (most recent call last):
  File "/home/YJY015/code/file_info/wget_download.py", line 734, in download_wget
    self.record_datas()
  File "/home/YJY015/code/file_info/wget_download.py", line 667, in record_datas
    self.record_data(self.localfilename)
  File "/home/YJY015/code/file_info/wget_download.py", line 459, in record_data
    self.db_file_size=os.path.getsize(self.downloadfullpathname)
  File "/root/anaconda3/lib/python3.7/genericpath.py", line 50, in getsize
    return os.stat(filename).st_size
FileNotFoundError: [Errno 2] No such file or directory: '/home/YJY015///data//hybrid/SWPC/json/goes_int_proton/202006/20200616/differential-protons-1-day_20200616_084500.json'


During handling of the above exception, another exception occurred:

Traceback (most recent call last):
  File "/home/YJY015/code/download.py", line 73, in download_wget_manually
    wg.start(starttime,endtime) ####传入时间，与系统时间比较，如果大于系统时间(有bug,系统时间错误，就是bug)
  File "/home/YJY015/code/file_info/wget_download.py", line 876, in start
    raise Exception(traceback.format_exc())
Exception: Traceback (most recent call last):
  File "/home/YJY015/code/file_info/wget_download.py", line 734, in download_wget
    self.record_datas()
  File "/home/YJY015/code/file_info/wget_download.py", line 667, in record_datas
    self.record_data(self.localfilename)
  File "/home/YJY015/code/file_info/wget_download.py", line 459, in record_data
    self.db_file_size=os.path.getsize(self.downloadfullpathname)
  File "/root/anaconda3/lib/python3.7/genericpath.py", line 50, in getsize
    return os.stat(filename).st_size
FileNotFoundError: [Errno 2] No such file or directory: '/home/YJY015///data//hybrid/SWPC/json/goes_int_proton/202006/20200616/differential-protons-1-day_20200616_084500.json'

During handling of the above exception, another exception occurred:

Traceback (most recent call last):
  File "/home/YJY015/code/file_info/wget_download.py", line 873, in start
    self.download_wget(starttime, endtime)
  File "/home/YJY015/code/file_info/wget_download.py", line 741, in download_wget
    raise Exception(traceback.format_exc())
Exception: Traceback (most recent call last):
  File "/home/YJY015/code/file_info/wget_download.py", line 734, in download_wget
    self.record_datas()
  File "/home/YJY015/code/file_info/wget_download.py", line 667, in record_datas
    self.record_data(self.localfilename)
  File "/home/YJY015/code/file_info/wget_download.py", line 459, in record_data
    self.db_file_size=os.path.getsize(self.downloadfullpathname)
  File "/root/anaconda3/lib/python3.7/genericpath.py", line 50, in getsize
    return os.stat(filename).st_size
FileNotFoundError: [Errno 2] No such file or directory: '/home/YJY015///data//hybrid/SWPC/json/goes_int_proton/202006/20200616/differential-protons-1-day_20200616_084500.json'



[root][2020-06-16 16:45:06][2020-06-16 16:45:17][    129495]:  Traceback (most recent call last):
  File "/home/YJY015/code/file_info/wget_download.py", line 734, in download_wget
    self.record_datas()
  File "/home/YJY015/code/file_info/wget_download.py", line 667, in record_datas
    self.record_data(self.localfilename)
  File "/home/YJY015/code/file_info/wget_download.py", line 459, in record_data
    self.db_file_size=os.path.getsize(self.downloadfullpathname)
  File "/root/anaconda3/lib/python3.7/genericpath.py", line 50, in getsize
    return os.stat(filename).st_size
FileNotFoundError: [Errno 2] No such file or directory: '/home/YJY015///data//hybrid/SWPC/json/goes_int_proton/202006/20200616/differential-protons-1-day_20200616_084500.json'

During handling of the above exception, another exception occurred:

Traceback (most recent call last):
  File "/home/YJY015/code/file_info/wget_download.py", line 873, in start
    self.download_wget(starttime, endtime)
  File "/home/YJY015/code/file_info/wget_download.py", line 741, in download_wget
    raise Exception(traceback.format_exc())
Exception: Traceback (most recent call last):
  File "/home/YJY015/code/file_info/wget_download.py", line 734, in download_wget
    self.record_datas()
  File "/home/YJY015/code/file_info/wget_download.py", line 667, in record_datas
    self.record_data(self.localfilename)
  File "/home/YJY015/code/file_info/wget_download.py", line 459, in record_data
    self.db_file_size=os.path.getsize(self.downloadfullpathname)
  File "/root/anaconda3/lib/python3.7/genericpath.py", line 50, in getsize
    return os.stat(filename).st_size
FileNotFoundError: [Errno 2] No such file or directory: '/home/YJY015///data//hybrid/SWPC/json/goes_int_proton/202006/20200616/differential-protons-1-day_20200616_084500.json'


During handling of the above exception, another exception occurred:

Traceback (most recent call last):
  File "/home/YJY015/code/download.py", line 73, in download_wget_manually
    wg.start(starttime,endtime) ####传入时间，与系统时间比较，如果大于系统时间(有bug,系统时间错误，就是bug)
  File "/home/YJY015/code/file_info/wget_download.py", line 876, in start
    raise Exception(traceback.format_exc())
Exception: Traceback (most recent call last):
  File "/home/YJY015/code/file_info/wget_download.py", line 734, in download_wget
    self.record_datas()
  File "/home/YJY015/code/file_info/wget_download.py", line 667, in record_datas
    self.record_data(self.localfilename)
  File "/home/YJY015/code/file_info/wget_download.py", line 459, in record_data
    self.db_file_size=os.path.getsize(self.downloadfullpathname)
  File "/root/anaconda3/lib/python3.7/genericpath.py", line 50, in getsize
    return os.stat(filename).st_size
FileNotFoundError: [Errno 2] No such file or directory: '/home/YJY015///data//hybrid/SWPC/json/goes_int_proton/202006/20200616/differential-protons-1-day_20200616_084500.json'

During handling of the above exception, another exception occurred:

Traceback (most recent call last):
  File "/home/YJY015/code/file_info/wget_download.py", line 873, in start
    self.download_wget(starttime, endtime)
  File "/home/YJY015/code/file_info/wget_download.py", line 741, in download_wget
    raise Exception(traceback.format_exc())
Exception: Traceback (most recent call last):
  File "/home/YJY015/code/file_info/wget_download.py", line 734, in download_wget
    self.record_datas()
  File "/home/YJY015/code/file_info/wget_download.py", line 667, in record_datas
    self.record_data(self.localfilename)
  File "/home/YJY015/code/file_info/wget_download.py", line 459, in record_data
    self.db_file_size=os.path.getsize(self.downloadfullpathname)
  File "/root/anaconda3/lib/python3.7/genericpath.py", line 50, in getsize
    return os.stat(filename).st_size
FileNotFoundError: [Errno 2] No such file or directory: '/home/YJY015///data//hybrid/SWPC/json/goes_int_proton/202006/20200616/differential-protons-1-day_20200616_084500.json'



During handling of the above exception, another exception occurred:

Traceback (most recent call last):
  File "/home/YJY015/code/download.py", line 174, in <module>
    download_wget_manually(category_abbr_en,starttime,endtime,searchinfos)
  File "/home/YJY015/code/download.py", line 75, in download_wget_manually
    raise Exception(traceback.format_exc())
Exception: Traceback (most recent call last):
  File "/home/YJY015/code/file_info/wget_download.py", line 734, in download_wget
    self.record_datas()
  File "/home/YJY015/code/file_info/wget_download.py", line 667, in record_datas
    self.record_data(self.localfilename)
  File "/home/YJY015/code/file_info/wget_download.py", line 459, in record_data
    self.db_file_size=os.path.getsize(self.downloadfullpathname)
  File "/root/anaconda3/lib/python3.7/genericpath.py", line 50, in getsize
    return os.stat(filename).st_size
FileNotFoundError: [Errno 2] No such file or directory: '/home/YJY015///data//hybrid/SWPC/json/goes_int_proton/202006/20200616/differential-protons-1-day_20200616_084500.json'

During handling of the above exception, another exception occurred:

Traceback (most recent call last):
  File "/home/YJY015/code/file_info/wget_download.py", line 873, in start
    self.download_wget(starttime, endtime)
  File "/home/YJY015/code/file_info/wget_download.py", line 741, in download_wget
    raise Exception(traceback.format_exc())
Exception: Traceback (most recent call last):
  File "/home/YJY015/code/file_info/wget_download.py", line 734, in download_wget
    self.record_datas()
  File "/home/YJY015/code/file_info/wget_download.py", line 667, in record_datas
    self.record_data(self.localfilename)
  File "/home/YJY015/code/file_info/wget_download.py", line 459, in record_data
    self.db_file_size=os.path.getsize(self.downloadfullpathname)
  File "/root/anaconda3/lib/python3.7/genericpath.py", line 50, in getsize
    return os.stat(filename).st_size
FileNotFoundError: [Errno 2] No such file or directory: '/home/YJY015///data//hybrid/SWPC/json/goes_int_proton/202006/20200616/differential-protons-1-day_20200616_084500.json'


During handling of the above exception, another exception occurred:

Traceback (most recent call last):
  File "/home/YJY015/code/download.py", line 73, in download_wget_manually
    wg.start(starttime,endtime) ####传入时间，与系统时间比较，如果大于系统时间(有bug,系统时间错误，就是bug)
  File "/home/YJY015/code/file_info/wget_download.py", line 876, in start
    raise Exception(traceback.format_exc())
Exception: Traceback (most recent call last):
  File "/home/YJY015/code/file_info/wget_download.py", line 734, in download_wget
    self.record_datas()
  File "/home/YJY015/code/file_info/wget_download.py", line 667, in record_datas
    self.record_data(self.localfilename)
  File "/home/YJY015/code/file_info/wget_download.py", line 459, in record_data
    self.db_file_size=os.path.getsize(self.downloadfullpathname)
  File "/root/anaconda3/lib/python3.7/genericpath.py", line 50, in getsize
    return os.stat(filename).st_size
FileNotFoundError: [Errno 2] No such file or directory: '/home/YJY015///data//hybrid/SWPC/json/goes_int_proton/202006/20200616/differential-protons-1-day_20200616_084500.json'

During handling of the above exception, another exception occurred:

Traceback (most recent call last):
  File "/home/YJY015/code/file_info/wget_download.py", line 873, in start
    self.download_wget(starttime, endtime)
  File "/home/YJY015/code/file_info/wget_download.py", line 741, in download_wget
    raise Exception(traceback.format_exc())
Exception: Traceback (most recent call last):
  File "/home/YJY015/code/file_info/wget_download.py", line 734, in download_wget
    self.record_datas()
  File "/home/YJY015/code/file_info/wget_download.py", line 667, in record_datas
    self.record_data(self.localfilename)
  File "/home/YJY015/code/file_info/wget_download.py", line 459, in record_data
    self.db_file_size=os.path.getsize(self.downloadfullpathname)
  File "/root/anaconda3/lib/python3.7/genericpath.py", line 50, in getsize
    return os.stat(filename).st_size
FileNotFoundError: [Errno 2] No such file or directory: '/home/YJY015///data//hybrid/SWPC/json/goes_int_proton/202006/20200616/differential-protons-1-day_20200616_084500.json'




