[root][2020-07-09 11:00:03][2020-07-09 11:00:45][    260473]:  Traceback (most recent call last):
  File "/home/YJY015/code/file_info/wget_download.py", line 738, in download_wget
    self.record_datas()
  File "/home/YJY015/code/file_info/wget_download.py", line 714, in record_datas
    retcode = self.record_data( self.localfilename )
  File "/home/YJY015/code/file_info/wget_download.py", line 458, in record_data
    self.db_file_size=os.path.getsize(self.downloadfullpathname)
  File "/root/anaconda3/lib/python3.7/genericpath.py", line 50, in getsize
    return os.stat(filename).st_size
FileNotFoundError: [Errno 2] No such file or directory: '/home/YJY015///data//solar/GMU/SOHO/COR2/202007/20200708/20200708_1600_c2_20200708_161200.gif'

During handling of the above exception, another exception occurred:

Traceback (most recent call last):
  File "/home/YJY015/code/file_info/wget_download.py", line 882, in start
    self.download_wget(starttime, endtime)
  File "/home/YJY015/code/file_info/wget_download.py", line 745, in download_wget
    raise Exception(traceback.format_exc())
Exception: Traceback (most recent call last):
  File "/home/YJY015/code/file_info/wget_download.py", line 738, in download_wget
    self.record_datas()
  File "/home/YJY015/code/file_info/wget_download.py", line 714, in record_datas
    retcode = self.record_data( self.localfilename )
  File "/home/YJY015/code/file_info/wget_download.py", line 458, in record_data
    self.db_file_size=os.path.getsize(self.downloadfullpathname)
  File "/root/anaconda3/lib/python3.7/genericpath.py", line 50, in getsize
    return os.stat(filename).st_size
FileNotFoundError: [Errno 2] No such file or directory: '/home/YJY015///data//solar/GMU/SOHO/COR2/202007/20200708/20200708_1600_c2_20200708_161200.gif'


During handling of the above exception, another exception occurred:

Traceback (most recent call last):
  File "/home/YJY015/code/download.py", line 69, in download_wget_manually
    wg.start(starttime,endtime) ####传入时间，与系统时间比较，如果大于系统时间(有bug,系统时间错误，就是bug)
  File "/home/YJY015/code/file_info/wget_download.py", line 885, in start
    raise Exception(traceback.format_exc())
Exception: Traceback (most recent call last):
  File "/home/YJY015/code/file_info/wget_download.py", line 738, in download_wget
    self.record_datas()
  File "/home/YJY015/code/file_info/wget_download.py", line 714, in record_datas
    retcode = self.record_data( self.localfilename )
  File "/home/YJY015/code/file_info/wget_download.py", line 458, in record_data
    self.db_file_size=os.path.getsize(self.downloadfullpathname)
  File "/root/anaconda3/lib/python3.7/genericpath.py", line 50, in getsize
    return os.stat(filename).st_size
FileNotFoundError: [Errno 2] No such file or directory: '/home/YJY015///data//solar/GMU/SOHO/COR2/202007/20200708/20200708_1600_c2_20200708_161200.gif'

During handling of the above exception, another exception occurred:

Traceback (most recent call last):
  File "/home/YJY015/code/file_info/wget_download.py", line 882, in start
    self.download_wget(starttime, endtime)
  File "/home/YJY015/code/file_info/wget_download.py", line 745, in download_wget
    raise Exception(traceback.format_exc())
Exception: Traceback (most recent call last):
  File "/home/YJY015/code/file_info/wget_download.py", line 738, in download_wget
    self.record_datas()
  File "/home/YJY015/code/file_info/wget_download.py", line 714, in record_datas
    retcode = self.record_data( self.localfilename )
  File "/home/YJY015/code/file_info/wget_download.py", line 458, in record_data
    self.db_file_size=os.path.getsize(self.downloadfullpathname)
  File "/root/anaconda3/lib/python3.7/genericpath.py", line 50, in getsize
    return os.stat(filename).st_size
FileNotFoundError: [Errno 2] No such file or directory: '/home/YJY015///data//solar/GMU/SOHO/COR2/202007/20200708/20200708_1600_c2_20200708_161200.gif'



[root][2020-07-09 11:00:03][2020-07-09 11:00:45][    260473]:  Traceback (most recent call last):
  File "/home/YJY015/code/file_info/wget_download.py", line 738, in download_wget
    self.record_datas()
  File "/home/YJY015/code/file_info/wget_download.py", line 714, in record_datas
    retcode = self.record_data( self.localfilename )
  File "/home/YJY015/code/file_info/wget_download.py", line 458, in record_data
    self.db_file_size=os.path.getsize(self.downloadfullpathname)
  File "/root/anaconda3/lib/python3.7/genericpath.py", line 50, in getsize
    return os.stat(filename).st_size
FileNotFoundError: [Errno 2] No such file or directory: '/home/YJY015///data//solar/GMU/SOHO/COR2/202007/20200708/20200708_1600_c2_20200708_161200.gif'

During handling of the above exception, another exception occurred:

Traceback (most recent call last):
  File "/home/YJY015/code/file_info/wget_download.py", line 882, in start
    self.download_wget(starttime, endtime)
  File "/home/YJY015/code/file_info/wget_download.py", line 745, in download_wget
    raise Exception(traceback.format_exc())
Exception: Traceback (most recent call last):
  File "/home/YJY015/code/file_info/wget_download.py", line 738, in download_wget
    self.record_datas()
  File "/home/YJY015/code/file_info/wget_download.py", line 714, in record_datas
    retcode = self.record_data( self.localfilename )
  File "/home/YJY015/code/file_info/wget_download.py", line 458, in record_data
    self.db_file_size=os.path.getsize(self.downloadfullpathname)
  File "/root/anaconda3/lib/python3.7/genericpath.py", line 50, in getsize
    return os.stat(filename).st_size
FileNotFoundError: [Errno 2] No such file or directory: '/home/YJY015///data//solar/GMU/SOHO/COR2/202007/20200708/20200708_1600_c2_20200708_161200.gif'


During handling of the above exception, another exception occurred:

Traceback (most recent call last):
  File "/home/YJY015/code/download.py", line 69, in download_wget_manually
    wg.start(starttime,endtime) ####传入时间，与系统时间比较，如果大于系统时间(有bug,系统时间错误，就是bug)
  File "/home/YJY015/code/file_info/wget_download.py", line 885, in start
    raise Exception(traceback.format_exc())
Exception: Traceback (most recent call last):
  File "/home/YJY015/code/file_info/wget_download.py", line 738, in download_wget
    self.record_datas()
  File "/home/YJY015/code/file_info/wget_download.py", line 714, in record_datas
    retcode = self.record_data( self.localfilename )
  File "/home/YJY015/code/file_info/wget_download.py", line 458, in record_data
    self.db_file_size=os.path.getsize(self.downloadfullpathname)
  File "/root/anaconda3/lib/python3.7/genericpath.py", line 50, in getsize
    return os.stat(filename).st_size
FileNotFoundError: [Errno 2] No such file or directory: '/home/YJY015///data//solar/GMU/SOHO/COR2/202007/20200708/20200708_1600_c2_20200708_161200.gif'

During handling of the above exception, another exception occurred:

Traceback (most recent call last):
  File "/home/YJY015/code/file_info/wget_download.py", line 882, in start
    self.download_wget(starttime, endtime)
  File "/home/YJY015/code/file_info/wget_download.py", line 745, in download_wget
    raise Exception(traceback.format_exc())
Exception: Traceback (most recent call last):
  File "/home/YJY015/code/file_info/wget_download.py", line 738, in download_wget
    self.record_datas()
  File "/home/YJY015/code/file_info/wget_download.py", line 714, in record_datas
    retcode = self.record_data( self.localfilename )
  File "/home/YJY015/code/file_info/wget_download.py", line 458, in record_data
    self.db_file_size=os.path.getsize(self.downloadfullpathname)
  File "/root/anaconda3/lib/python3.7/genericpath.py", line 50, in getsize
    return os.stat(filename).st_size
FileNotFoundError: [Errno 2] No such file or directory: '/home/YJY015///data//solar/GMU/SOHO/COR2/202007/20200708/20200708_1600_c2_20200708_161200.gif'



During handling of the above exception, another exception occurred:

Traceback (most recent call last):
  File "/home/YJY015/code/download.py", line 170, in <module>
    download_wget_manually(category_abbr_en,starttime,endtime,searchinfos)
  File "/home/YJY015/code/download.py", line 71, in download_wget_manually
    raise Exception(traceback.format_exc())
Exception: Traceback (most recent call last):
  File "/home/YJY015/code/file_info/wget_download.py", line 738, in download_wget
    self.record_datas()
  File "/home/YJY015/code/file_info/wget_download.py", line 714, in record_datas
    retcode = self.record_data( self.localfilename )
  File "/home/YJY015/code/file_info/wget_download.py", line 458, in record_data
    self.db_file_size=os.path.getsize(self.downloadfullpathname)
  File "/root/anaconda3/lib/python3.7/genericpath.py", line 50, in getsize
    return os.stat(filename).st_size
FileNotFoundError: [Errno 2] No such file or directory: '/home/YJY015///data//solar/GMU/SOHO/COR2/202007/20200708/20200708_1600_c2_20200708_161200.gif'

During handling of the above exception, another exception occurred:

Traceback (most recent call last):
  File "/home/YJY015/code/file_info/wget_download.py", line 882, in start
    self.download_wget(starttime, endtime)
  File "/home/YJY015/code/file_info/wget_download.py", line 745, in download_wget
    raise Exception(traceback.format_exc())
Exception: Traceback (most recent call last):
  File "/home/YJY015/code/file_info/wget_download.py", line 738, in download_wget
    self.record_datas()
  File "/home/YJY015/code/file_info/wget_download.py", line 714, in record_datas
    retcode = self.record_data( self.localfilename )
  File "/home/YJY015/code/file_info/wget_download.py", line 458, in record_data
    self.db_file_size=os.path.getsize(self.downloadfullpathname)
  File "/root/anaconda3/lib/python3.7/genericpath.py", line 50, in getsize
    return os.stat(filename).st_size
FileNotFoundError: [Errno 2] No such file or directory: '/home/YJY015///data//solar/GMU/SOHO/COR2/202007/20200708/20200708_1600_c2_20200708_161200.gif'


During handling of the above exception, another exception occurred:

Traceback (most recent call last):
  File "/home/YJY015/code/download.py", line 69, in download_wget_manually
    wg.start(starttime,endtime) ####传入时间，与系统时间比较，如果大于系统时间(有bug,系统时间错误，就是bug)
  File "/home/YJY015/code/file_info/wget_download.py", line 885, in start
    raise Exception(traceback.format_exc())
Exception: Traceback (most recent call last):
  File "/home/YJY015/code/file_info/wget_download.py", line 738, in download_wget
    self.record_datas()
  File "/home/YJY015/code/file_info/wget_download.py", line 714, in record_datas
    retcode = self.record_data( self.localfilename )
  File "/home/YJY015/code/file_info/wget_download.py", line 458, in record_data
    self.db_file_size=os.path.getsize(self.downloadfullpathname)
  File "/root/anaconda3/lib/python3.7/genericpath.py", line 50, in getsize
    return os.stat(filename).st_size
FileNotFoundError: [Errno 2] No such file or directory: '/home/YJY015///data//solar/GMU/SOHO/COR2/202007/20200708/20200708_1600_c2_20200708_161200.gif'

During handling of the above exception, another exception occurred:

Traceback (most recent call last):
  File "/home/YJY015/code/file_info/wget_download.py", line 882, in start
    self.download_wget(starttime, endtime)
  File "/home/YJY015/code/file_info/wget_download.py", line 745, in download_wget
    raise Exception(traceback.format_exc())
Exception: Traceback (most recent call last):
  File "/home/YJY015/code/file_info/wget_download.py", line 738, in download_wget
    self.record_datas()
  File "/home/YJY015/code/file_info/wget_download.py", line 714, in record_datas
    retcode = self.record_data( self.localfilename )
  File "/home/YJY015/code/file_info/wget_download.py", line 458, in record_data
    self.db_file_size=os.path.getsize(self.downloadfullpathname)
  File "/root/anaconda3/lib/python3.7/genericpath.py", line 50, in getsize
    return os.stat(filename).st_size
FileNotFoundError: [Errno 2] No such file or directory: '/home/YJY015///data//solar/GMU/SOHO/COR2/202007/20200708/20200708_1600_c2_20200708_161200.gif'




